Workbook
Name Achats_finances: [1]!Pole3[Achats_finances]
Name Cellule_stratégique_Qualité_Projets: [1]!Pole6[Cellule_stratégique_Qualité_Projets]
Name Détails_finalités: [1]Liste!$C$1:$C$98
Name Infrastructure_logistique: [1]!Pole5[Infrastructure_logistique]
Name Listedépartements: [1]Liste!$B$1:$B$98
Name Médical_Pharmacie: [1]!Pole1[Médical_Pharmacie]
Name Ressources_humaines_Trajet_patient_communications: [1]!Pole4[Ressources_humaines_Trajet_patient_communications]
Name Soins: [1]!Pole2[Soins]
Name Système_information: [1]!Pole7[Système_information]
Name Traitements_marchés: [1]!Tableau19[Traitements_marchés]

Sheet 1 Lancement utilisateur 
B1: DATE DERNIERE MAJ : 17/09/2025
A2: Où trouver cette fiche sur l'intranet : | B2: https://intranetsites.chrcitadelle.be/Achats et magasins/99 Plateforme échange/A - FICHE DE LANCEMENT ACHATS
A4: FICHE A RENVOYER COMPLETEE A : | B4: achats@citadelle.be (ou à votre interlocuteur habituel au service achats)
A6: FICHE DE DEMANDE DE LANCEMENT D'UN ACHAT
A7: Date :
A8: Service demandeur :
A9: Nom et tél/mail du demandeur :
A10: Catégorie d'achat : (choisir parmi les options) Liée à la nature du bien/service acheté, pas au service demandeur. Ex. achat d'un siège de bureau pour le service de gynécologie => choisir la catégorie MOBILIER
A12: Informations de Base et Motivation
A13: Objet : que souhaitez-vous acheter ? Si matériel/équipement, indiquer marque et modèle du matériel souhaité
A14: Raison de l'achat : (choisir parmi les options)
A15: Motivation de l'achat : en quoi cet achat est ESSENTIEL pour l'activité de l'hôpital. Si remplacement, spécifier les circonstances de la casse/perte
A16: Si remplacement de matériel, indiquer marque/modèle/année du matériel à remplacer
A17: Reprise souhaitée de l'ancien matériel par la firme (Choisir parmi les options)
A18: Compatibilité avec du matériel déjà présent dans l'institution ? Si oui, veuillez spécifier lequel :
... A61: Tests à organiser (Oui/Non)

Sheet 2 Présentation
A2: FICHE DE DEMANDE DE LANCEMENT D'UN ACHAT
A3: Service demandeur : | B3: ='1 Lancement utilisateur '!B8 -> 0
A5: Informations de Base et Motivation
A6: Objet : que souhaitez-vous acheter ? Si matériel, indiquer marque et modèle du matériel souhaité | B6: ='1 Lancement utilisateur '!B13 -> 0
A7: Raison de l'achat : | B7: ='1 Lancement utilisateur '!B14 -> 0
A8: Motivation de l'achat : en quoi cet achat est ESSENTIEL pour l'activité de l'hôpital. Si remplacement, spécifier les circonstances de la casse/perte | B8: ='1 Lancement utilisateur '!B15 -> 0
A9: Si remplacement de matériel, indiquer marque/modèle/année du matériel à remplacer | B9: ='1 Lancement utilisateur '!B16 -> 0
A10: Site(s) concerné(s) | B10: ='1 Lancement utilisateur '!B19 -> 0
A11: Local existant (lequel ?) ou nécessité d'un local supplémentaire ? | B11: ='1 Lancement utilisateur '!B20 -> 0
A12: Date de mise en service /début souhaitée : | B12: ='1 Lancement utilisateur '!B23 -> 0
A14: Budget / Estimation
A15: Quantité : (quantité totale) | B15: ='1 Lancement utilisateur '!B26 -> 0
A16: Montant total € TVAC : | B16: ='1 Lancement utilisateur '!B28 -> 0
A17: Si applicable => Consommables :
A18: Pour les équipements, y a-t-il des consommables dédiés ? | B18: ='1 Lancement utilisateur '!B31 -> 0
A19: Estimation des consommables € TVAC pour 1 an | B19: ='1 Lancement utilisateur '!B32 -> 0
A20: Si applicable => Maintenance :
A21: Faut-il prévoir de la maintenance ? | B21: ='1 Lancement utilisateur '!B34 -> 0
A22: Estimation de la maintenance € TVAC pendant 1 an | B22: ='1 Lancement utilisateur '!B35 -> 0
A24: Rentabilité
A25: Rentabilité : Informations concernant la rentabilité de l'achat/dépense Ex : refacturation au patient / optimisations des coûts / efficience du personnel / etc. | B25: ='1 Lancement utilisateur '!B39 -> 0
A26: Le projet fait-il l'objet d'un subside/convention ? (Oui/Non, si OUI préciser) | B26: ='1 Lancement utilisateur '!B40 -> 0
A27: Pour le matériel MEDICAL > 30.000 € TVAC => Calcul du coût réel pour l'hôpital :
A28: Nombre de patients et/ou procédures par an
A29: Code INAMI de la prestation ou du forfait
A30: Montant du code INAMI en € (si connu)
A31: % pour l'hôpital sur code INAMI (si connu)
A32: Ressources humaines nécessaires pour réaliser la prestation (spécifier ETP ou nombre d'heure par catégorie)
A33: Veuillez préciser la ou les catégories : infirmière/aide soignante/aide logistique, etc.
A35: Autres parties prenantes (internes à l'institution)
A36: Montant travaux nécessaires : | B36: ='1 Lancement utilisateur '!B51 -> 0
A37: Coûts informatiques € TVAC | B37: ='1 Lancement utilisateur '!B53 -> 0
A38: RGPD : | B38: ='1 Lancement utilisateur '!B54 -> 0
A39: SIPP : | B39: ='1 Lancement utilisateur '!B55 -> 0
A40: Hygiène : | B40: ='1 Lancement utilisateur '!B56 -> 0
A41: Autres parties prenantes : | B41: ='1 Lancement utilisateur '!B57 -> 0

Sheet Données
A1: Data
A3: Raison de l'achat | D3: Type de dossier | G3: Fiche acceptée | I3: Connexion IT
A4: Remplacement /éch standard matériel vétuste ou défectueux | D4: Achat | G4: Accepté | I4: Wifi
A5: Remplacement /éch standard matériel cassé par une mauvaise manipulation | D5: Location/leasing | G5: Accepté sous-réserve | I5: Câblage
A6: Remplacement matériel perdu | D6: Travaux | G6: Reporté | I6: Non
A7: Extension du parc existant / augmentation de l'activité existante | D7: Prestation de service | G7: Refusé
A8: Amélioration de l'existant (qualité, sécurité, innovation, etc.)
A9: Nouvelle activité
A10: Autre : spécifier dans la case suivante | D10: Consommables/Maintenance/Autre | H10: Mot de passe : | I10: FLA
D11: Oui | K11: Oui
D12: Non | K12: Non
D13: Ne sais pas | K13: En cours de demande à la cellule budget
A14: Catégorie d'achat | D14: Type de maintenance
A15: ALIMENTATION/HORECA | D15: Omnium
A16: ELECTRO/AUDIOVISUEL/TELEPHONIE | D16: Semi-omnium
A17: FLEET | D17: Préventive
A18: FOURNITURES BUREAU | D18: Interne à l'institution
A19: GESTION DES DECHETS | D19: Pas de maintenance
A20: HYGIENE/PROTECTION INDIVIDUELLE (EPI) | D20: Ne sais pas
A21: INFORMATIQUE HORS MEDICAL
A22: INFORMATIQUE MEDICAL | D22: Pas de consommables | I22: Aucune intervention de l'IT
A23: LABORATOIRE | D23: Consommables non-médicaux | I23: Equipement IT nécessaire (PC, serveur, etc)
A24: MEDICAL | D24: Consommables médicaux stériles | I24: Connexion nécessaire (Wifi, câble)
A25: MOBILIER | D25: Consommables médicaux non-stériles | I25: Intégration au système IT nécessaire (DPI, etc)
A26: NETTOYAGE/LINGERIE/TENUES | D26: Consommables médicaux stériles ET non-stériles | I26: Plusieurs interventions de l'IT (équipement, connexions, intégrations)
A27: PHARMACIE | D27: Ne sais pas | I27: Ne sais pas
A28: SERVICES GENERAUX
A29: TECHNIQUE ET INFRASTRUCTURE
A32: Mot de passe : fis

Sheet 4 Serv Technique fiche
A1: Informations de Base
A2: Nom du projet : | C2: ='1 Lancement utilisateur '!B13 -> 0
A3: Acheteur : | C3: ='1 Lancement utilisateur '!B10 -> 0
A4: Budget HTVA estimé technique / travaux :
A5: Date de la fiche :
A6: Rédacteur:
A8: Inventaire et disponibilité
A9: Matériel disponible :
A10: Numéro du matériel :
A11: Remarques:
A13: Réception
A14: Lieu de livraison :
A15: Déchargement :
A16: Docs spécifiques :
A17: Réception provisoire:
... A80: Budget complémentaire - hors budget principal
A81: Dépenses : | B81: 1
B82: 2
B83: 3
B84: …
A85: Prestations internes : | B85: 1
B86: 2
B87: 3
B88: …
A89: Autres :
A90: Total achats indirects :
A91: Total ressources
A92: TOTAL :
A93: Remarques :
A95: Remarques générales
A96: Remarque : | B96: 1
B97: 2
B98: 3
B99: …
A100: Annexes: | B100: 1
B101: 2
B102: 3
B103: …
A105: Approbation responsable technique
A106: Nom prénom :
...

Sheet 5 Serv Technique exigences
B1: Nom du projet : | D1: ='1 Lancement utilisateur '!B13 -> 0
B2: Acheteur : | D2: ='1 Lancement utilisateur '!B10 -> 0
A4: Concat lot | B4: Référence | C4: Secteur | D4: Type d'exigence | E4: Exigences | F4: Commentaires / remarques
A5: =_xlfn.CONCAT(#REF!,#REF!) -> #REF! | B5: T001
A6: =_xlfn.CONCAT(#REF!,#REF!) -> #REF! | B6: T002
A7: =_xlfn.CONCAT(#REF!,#REF!) -> #REF! | B7: T003
A8: =_xlfn.CONCAT(#REF!,#REF!) -> #REF! | B8: T004
A9: =_xlfn.CONCAT(#REF!,#REF!) -> #REF! | B9: T005
A10: =_xlfn.CONCAT(#REF!,#REF!) -> #REF! | B10: T006
A11: =_xlfn.CONCAT(#REF!,#REF!) -> #REF! | B11: T007
A12: =_xlfn.CONCAT(#REF!,#REF!) -> #REF! | B12: T008
A13: =_xlfn.CONCAT(#REF!,#REF!) -> #REF! | B13: T009
A14: =_xlfn.CONCAT(#REF!,#REF!) -> #REF! | B14: T010
A15: =_xlfn.CONCAT(#REF!,#REF!) -> #REF! | B15: T011
A16: =_xlfn.CONCAT(#REF!,#REF!) -> #REF! | B16: T012
... A104: =_xlfn.CONCAT(#REF!,#REF!) -> #REF! | B104: T100

Sheet 6 IT check list annexes
A1: Nom du projet : | D1: ='1 Lancement utilisateur '!B13 -> 0
A2: Acheteur : | D2: ='1 Lancement utilisateur '!B10 -> 0
A4: Nom de l'annexe | B4: A insérer dans le CSC? | C4: A modifier? | D4: Commentaires / remarques
A5: Charte sur l'utilisation et la sécurisation du système de l'information du C.H.R. de la Citadelle
A6: Environnement d’exécution
A7: Environnement opérationnelles
A8: Exigences de sécurité
A9: Formulaire SSO
A10: Interopérabilité avec les systèmes du C.H.R.
A11: Conventions de nommage et définition

Sheet 7  IT exigences
B1: Nom du projet : | D1: ='1 Lancement utilisateur '!B13 -> 0
B2: Acheteur : | D2: ='1 Lancement utilisateur '!B10 -> 0
A4: Concat lot | B4: Référence | C4: Type | D4: Type d'exigence | E4: Exigences | F4: Commentaires / remarques
A5: =_xlfn.CONCAT(#REF!,#REF!) -> #REF! | B5: I001
A6: =_xlfn.CONCAT(#REF!,#REF!) -> #REF! | B6: I002
A7: =_xlfn.CONCAT(#REF!,#REF!) -> #REF! | B7: I003
A8: =_xlfn.CONCAT(#REF!,#REF!) -> #REF! | B8: I004
A9: =_xlfn.CONCAT(#REF!,#REF!) -> #REF! | B9: I005
A10: =_xlfn.CONCAT(#REF!,#REF!) -> #REF! | B10: I006
A11: =_xlfn.CONCAT(#REF!,#REF!) -> #REF! | B11: I007
A12: =_xlfn.CONCAT(#REF!,#REF!) -> #REF! | B12: I008
A13: =_xlfn.CONCAT(#REF!,#REF!) -> #REF! | B13: I009
A14: =_xlfn.CONCAT(#REF!,#REF!) -> #REF! | B14: I010
A15: =_xlfn.CONCAT(#REF!,#REF!) -> #REF! | B15: I011
A16: =_xlfn.CONCAT(#REF!,#REF!) -> #REF! | B16: I012
... A104: =_xlfn.CONCAT(#REF!,#REF!) -> #REF! | B104: I100

Sheet Data
A1: Oui | D1: Aucun | E1: Tous | G1: Exigence obligatoire | I1: Matériel principal | K1: Service demandeur | M1: Interne | O1: en nbre de procédures | Q1: par an | T1: Oui
A2: Non | D2: Tous | E2: Poste 01 | G2: Critère d'attribution | I2: Disposable | M2: Externe | O2: en nbre de pièces | Q2: pour la durée du marché | T2: Non
D3: Lot 01 | E3: Poste 02 | G3: Sélection qualitative | I3: Maintenance | M3: Autre
D4: Lot 02 | E4: Poste 03
D5: Lot 03 | E5: Poste 04
D6: Lot 04 | E6: Poste 05
D7: Lot 05 | E7: Poste 06
D8: Lot 06 | E8: Poste 07
D9: Lot 07 | E9: Poste 08
D10: Lot 08 | E10: Poste 09
D11: Lot 09 | E11: Poste 10
D12: Lot 10 | E12: Poste 11
D13: Lot 11 | E13: Poste 12
D14: Lot 12 | E14: Poste 13
D15: Lot 13 | E15: Poste 14
... D31: Lot 29 | E31: Poste 30
D32: Lot 30

Sheet Data 2
B3: Electricité
B4: HVAC
B5: Biomed
B6: Architecture
B7: Bâtiment
B8: Electro-méca
B9: Sites extérieurs
B10: Cellule projet
B14: Hardware
B15: Software
B16: Prestations
B17: Maintenance IT
B18: Connexion au réseau IT
